#Bugs
I had this error "TypeError: __init__() got an unexpected keyword argument 'providing_args'" while trying to migrate the allauth app.
I uninstalled django and reinstalled it, thereafter running python3 manage.py migrate which worked successfully.